Workbook

Sheet Bill Items
A1: 22-004I 10/03/2025 13:08:21 Page : 1
A2: Demolition & Initial Earthworks
A4: Bill | B4: Section | C4: Page | D4: Ref | E4: Description | F4: Quantity | G4: Unit | H4: Rate | I4: Extension | J4: Activity
A5: 1 | B5: 1 | C5: 1 | D5: A | E5: C EXISTING SITE / BUILDINGS / SERVICES C20 DEMOLITION Refer to 22-004-PR-W-0020 DGW1 Demolition Programme Rev A 2024-09-20 Phase 1A W+M Demolition (Above ground) Phase 1B W+M Demolition (Ground floor slabs) Phase 1C W+M Demolition (Basements) Phase 1D W+M Demolition (Foundations) PHASE 1 (Wolseley Plumb Centre) Asbestos removal | F5: 1 | G5: ITEM
A6: 1 | B6: 1 | C6: 1 | D6: B | E6: Demolition inc soft strip and grubbing up floor slab, foundations & drainage inc capping off | F6: 1 | G6: ITEM
A7: 1 | B7: 1 | C7: 1 | D7: C | E7: Process demolition arisings to 6f2 or import to 6f5, and stockpile crushed material in location to be agreed and to be used in backfilling basements and/or later piling platform works | F7: 1 | G7: ITEM
A8: 1 | B8: 1 | C8: 1 | D8: D | E8: Backfill of existing basement | F8: 1 | G8: ITEM
A9: 1 | B9: 1 | C9: 1 | D9: E | E9: Temporary works associated with the demolition methodology | F9: 1 | G9: ITEM
A10: 1 | B10: 1 | C10: 1 | D10: F | E10: Support of roads and the like Support of roads/ footpaths due to tightness of sight; potential temporary support required to form foundations; as drawing ZO-SL-DR-A-1010 P01 To be designed | F10: 1 | G10: ITEM
A11: 1 | B11: 1 | C11: 1 | D11: F | E11: Undertake all necessary works to retain the existing Highway | F11: 1 | G11: ITEM
A12: 1 | B12: 1 | C12: 1 | D12: G | E12: Mobility Store 2A - TC Phase B Demolition (Above ground) 2B - TC Phase A Demolition (Above ground) 2C - TC Phase A Demolition (Ground slabs) 2D - TC Phase A Demolition (Foundations) Asbestos removal | F12: 1 | G12: ITEM
A13: 1 | B13: 1 | C13: 1 | D13: H | E13: Existing gully pot, grate and frame to be taken up and removed from site, resulting void to be infilled with ST5 concrete mix and vibrated to remove any air bubbles generally | F13: 3 | G13: no
A14: 1 | B14: 1 | C14: 1 | D14: H | E14: Demolition inc soft strip and grubbing up floor slab, foundations & drainage inc capping off | F14: 1 | G14: ITEM
A15: 1 | B15: 1 | C15: 1 | D15: J | E15: Process demolition arisings to 6f2 or import to 6f5, and stockpile crushed material in location to be agreed and to be used in backfilling basements and/or later piling platform works | F15: 1 | G15: ITEM
A16: 1 | B16: 1 | C16: 1 | D16: K | E16: Backfill of existing basement | F16: 1 | G16: ITEM
... A35: 1 | B35: 1 | C35: 1 | D35: AD | E35: Traffic Management Traffic management alowance during demolition Phase for transportig materials between sites A & B | F35: 1 | G35: ITEM
A36: 1/1/1 | H36: To Collection: | I36: =I5+I6+I7+I12+I13+I14+I22+I23+I24+I29+I30+I32+I33+I34+I35 -> 0
A39: 22-004I 10/03/2025 13:08:21 Page : 2
A40: Demolition & Initial Earthworks
A42: Bill | B42: Section | C42: Page | D42: Ref | E42: Description | F42: Quantity | G42: Unit | H42: Rate | I42: Extension | J42: Activity
A43: 1 | B43: 1 | C43: 2 | D43: A | E43: Removing fittings and fixtures Side inlet gully to be taken up and removed from site, existing connection to be retained generally | F43: 1 | G43: no
A44: 1 | B44: 1 | C44: 2 | D44: B | E44: Existing non-illuminated traffic sign, pole and concrete foundation to be taken up and sign removed to tip generally | F44: 3 | G44: no
A45: 1 | B45: 1 | C45: 2 | D45: E | E45: Existing bin to be taken up and removed to tip off site and replaced with new bin, relocation position to be outlined by CoDC generally | F45: 1 | G45: no
A46: 1 | B46: 1 | C46: 2 | D46: F | E46: Works to existing Existing water stop valve to be adjusted to new footway level using class B Engineering bricks in class 1 mortar, any damaged valves to be replaced with new generally | F46: 4 | G46: no
A47: 1/1/2 | H47: To Collection: | I47: =I43+I44+I45+I46 -> 0
A50: 22-004I 10/03/2025 13:08:21 Page : 3
A51: Demolition & Initial Earthworks
A53: Bill | B53: Section | C53: Page | D53: Ref | E53: Description | F53: Quantity | G53: Unit | H53: Rate | I53: Extension | J53: Activity
A54: 1 | B54: 1 | C54: 3 | D54: A | E54: Works to existing Existing manhole/ inspection chambers, covers and frames to be adjusted to match new levels in carriageway, new D400 covers required and class B engineering brick with class 1 mortar bed to be finished surface course, any polished or damaged covers will need replacing generally | F54: 1 | G54: no
A55: 1 | B55: 1 | C55: 3 | D55: B | E55: Existing manhole/ inspection chambers, covers and frames located in the footway to be adjusted to match new levels, new covers and frames to be used generally | F55: 15 | G55: no
A56: 1 | B56: 1 | C56: 3 | D56: C | E56: Existing gas inspection chamber to be adjusted to suit new levels generally | F56: 1 | G56: no
A57: 1 | B57: 1 | C57: 3 | D57: F | E57: D GROUNDWORK D20 EXCAVATING AND FILLING Excavating To reduce levels 0.25 m maximum depth | F57: 83 | G57: m3
A58: 1/1/3 | H58: To Collection: | I58: =I54+I55+I56+I57 -> 0
A61: 22-004I 10/03/2025 13:08:21 Page : 4
A62: Demolition & Initial Earthworks
A64: Bill | B64: Section | C64: Page | D64: Ref | E64: Description | F64: Quantity | G64: Unit | H64: Rate | I64: Extension | J64: Activity
A65: 1 | B65: 1 | C65: 4 | D65: B | E65: Breaking out existing materials Break out existing kerb/ channel/ edging plus concrete bed and haunch; to be either reused or recycled for fill kerb/ channel or edging | F65: 106 | G65: m
A66: 1 | B66: 1 | C66: 4 | D66: C | E66: linear drain unit | F66: 57 | G66: m
A67: 1 | B67: 1 | C67: 4 | D67: D | E67: Disposal Disposal of water surface water | F67: 1 | G67: ITEM
A68: 1 | B68: 1 | C68: 4 | D68: E | E68: ground water | F68: 1 | G68: ITEM
...

Sheet Bill Summary
A8: Print Summary | E8: £ p
A9: Bill 1
C10: Demolition & Initial Earthworks | E10: ='Bill Items'!I85 -> 0
A11: Bill 2
C12: Substructure | E12: ='Bill Items'!I257 -> 0
A13: Bill 3
C14: Frame | E14: ='Bill Items'!I353 -> 0
A15: Bill 4
C16: Upper Floors | E16: ='Bill Items'!I418 -> 0
A17: Bill 5
C18: Roof | E18: ='Bill Items'!I605 -> 0
A19: Bill 6
C20: Stairs | E20: ='Bill Items'!I657 -> 0
A21: Bill 7
C22: External Walls | E22: ='Bill Items'!I840 -> 0
A23: Bill 8
C24: Windows & External Doors | E24: ='Bill Items'!I938 -> 0
A25: Bill 9
C26: Internal Walls | E26: ='Bill Items'!I1164 -> 0
A27: Bill 10
C28: Internal Doors | E28: ='Bill Items'!I1242 -> 0
A29: Bill 11
C30: Wall Finishes | E30: ='Bill Items'!I1341 -> 0
A31: Bill 12
C32: Floor Finishes | E32: ='Bill Items'!I1440 -> 0
A33: Bill 13
C34: Ceiling Finishes | E34: ='Bill Items'!I1512 -> 0
A35: Bill 14
C36: FF&E | E36: ='Bill Items'!I1581 -> 0
A37: Bill 15
C38: Sanitaryware | E38: ='Bill Items'!I1640 -> 0
A39: Bill 16
C40: M&E | E40: ='Bill Items'!I1701 -> 0
A41: Bill 17
C42: Phase 0 - Substructure Drainage | E42: ='Bill Items'!I1818 -> 0
A43: Bill 18
C44: Phase 1 - Cut & Fill | E44: ='Bill Items'!I1855 -> 0
A45: Bill 19
C46: Phase 1 - External Works | E46: ='Bill Items'!I1972 -> 0
A47: Bill 20
...

Sheet General Summary
A8: General Summary | E8: £ p
A9: Bill 1 | B9: Demolition & Initial Earthworks | E9: ='Bill Items'!I85 -> 0
A10: Bill 2 | B10: Substructure | E10: ='Bill Items'!I257 -> 0
A11: Bill 3 | B11: Frame | E11: ='Bill Items'!I353 -> 0
A12: Bill 4 | B12: Upper Floors | E12: ='Bill Items'!I418 -> 0
A13: Bill 5 | B13: Roof | E13: ='Bill Items'!I605 -> 0
A14: Bill 6 | B14: Stairs | E14: ='Bill Items'!I657 -> 0
A15: Bill 7 | B15: External Walls | E15: ='Bill Items'!I840 -> 0
A16: Bill 8 | B16: Windows & External Doors | E16: ='Bill Items'!I938 -> 0
A17: Bill 9 | B17: Internal Walls | E17: ='Bill Items'!I1164 -> 0
A18: Bill 10 | B18: Internal Doors | E18: ='Bill Items'!I1242 -> 0
A19: Bill 11 | B19: Wall Finishes | E19: ='Bill Items'!I1341 -> 0
A20: Bill 12 | B20: Floor Finishes | E20: ='Bill Items'!I1440 -> 0
A21: Bill 13 | B21: Ceiling Finishes | E21: ='Bill Items'!I1512 -> 0
A22: Bill 14 | B22: FF&E | E22: ='Bill Items'!I1581 -> 0
A23: Bill 15 | B23: Sanitaryware | E23: ='Bill Items'!I1640 -> 0
A24: Bill 16 | B24: M&E | E24: ='Bill Items'!I1701 -> 0
A25: Bill 17 | B25: Phase 0 - Substructure Drainage | E25: ='Bill Items'!I1818 -> 0
A26: Bill 18 | B26: Phase 1 - Cut & Fill | E26: ='Bill Items'!I1855 -> 0
A27: Bill 19 | B27: Phase 1 - External Works | E27: ='Bill Items'!I1972 -> 0
A28: Bill 20 | B28: Phase 1 - Drainage | E28: ='Bill Items'!I1995 -> 0
A29: Bill 21 | B29: Phase 1 - External Services | E29: ='Bill Items'!I2016 -> 0
A30: Bill 22 | B30: Phase 2 - Cut & Fill | E30: ='Bill Items'!I2051 -> 0
A31: Bill 23 | B31: Phase 2 - External Works | E31: ='Bill Items'!I2120 -> 0
A32: Bill 24 | B32: Phase 2 - Drainage | E32: ='Bill Items'!I2173 -> 0
A33: Bill 25 | B33: Phase 2 - External Services | E33: ='Bill Items'!I2194 -> 0
A34: Bill 26 | B34: Phase 3 - Cut & Fill | E34: ='Bill Items'!I2232 -> 0
A35: Bill 27 | B35: Phase 3 - External Works | E35: ='Bill Items'!I2313 -> 0
A36: Bill 28 | B36: Phase 3 - Drainage | E36: ='Bill Items'!I2355 -> 0
A37: Bill 29 | B37: Phase 3 - External Services | E37: ='Bill Items'!I2427 -> 0
A38: Bill 30 | B38: Phase 4 - Cut & Fill | E38: ='Bill Items'!I2452 -> 0
A39: Bill 31 | B39: Phase 4 - External Works | E39: ='Bill Items'!I2521 -> 0
A40: Bill 32 | B40: Phase 4 - Drainage | E40: ='Bill Items'!I2561 -> 0
A41: Bill 33 | B41: Phase 4 - External Services | E41: ='Bill Items'!I2605 -> 0
A42: Bill 34 | B42: Phase 5 - Cut & Fill | E42: ='Bill Items'!I2628 -> 0
A43: Bill 35 | B43: Phase 5 - External Works | E43: ='Bill Items'!I2730 -> 0
A44: Bill 36 | B44: Phase 5 - Drainage | E44: ='Bill Items'!I2775 -> 0
A45: Bill 37 | B45: Phase 5 - External Services | E45: ='Bill Items'!I2841 -> 0
A46: Bill 38 | B46: Phase 6 - Cut & Fill | E46: ='Bill Items'!I2863 -> 0
A47: Bill 39 | B47: Phase 6 - External Works | E47: ='Bill Items'!I2916 -> 0
...
